Workbook
Name AllowCats: '월요약'!$H$5:$H$12
Name StartBal: '기입장'!$B$3
Name Year: '기입장'!$B$2

Sheet 시작하기
B2: 대학생·청년 용돈기입장
B3: “소나기 맞으며 산 우산 값도 적어요”
B4: 소나기 그친 뒤 테마
B6: 사용 순서
B7: 1 | C7: ‘기입장’ 맨 위 파란 칸에 기준 연도와 처음 가진 돈(시작 잔액)을 적어요.
B8: 2 | C8: 받은 용돈은 ‘들어온 돈’, 쓴 돈은 ‘나간 돈’에 적으면 ‘잔액’이 저절로 계산돼요.
B9: 3 | C9: ‘월요약’에서 달마다 얼마를 받고 썼는지, 무엇에 많이 썼는지 그림으로 볼 수 있어요.
B10: 4 | C10: ‘저금목표’에 갖고 싶은 것과 금액을 적으면 얼마나 모았는지 막대로 보여 줘요.
B12: 처음 들어 있는 줄은 예시예요. 지우고 내 용돈으로 바꿔 쓰세요.
B14: 우체국보험 상담 안내 · 자유롭게 고쳐 쓰세요

Sheet 기입장
A1: 대학생·청년 용돈기입장
A2: 기준 연도 | B2: 2026 | C2: “소나기 맞으며 산 우산 값도 적어요”
A3: 시작 잔액(원) | B3: 0
A5: 날짜 | B5: 내용 | C5: 분류 | D5: 들어온 돈 | E5: 나간 돈 | F5: 잔액
A6: 46023 | B6: 이번 달 용돈 | D6: 300000 | F6: =IF(AND(D6="",E6=""),"",StartBal+SUM($D$6:D6)-SUM($E$6:E6)) -> 0
A7: 46027 | B7: 예시 지출 | C7: 교통 | E7: 70000 | F7: =IF(AND(D7="",E7=""),"",StartBal+SUM($D$6:D7)-SUM($E$6:E7)) -> 0
A8: 46034 | B8: 예시 지출 | C8: 교재·학습 | E8: 90000 | F8: =IF(AND(D8="",E8=""),"",StartBal+SUM($D$6:D8)-SUM($E$6:E8)) -> 0
A9: 46041 | B9: 예시 지출 | C9: 취미·여가 | E9: 50000 | F9: =IF(AND(D9="",E9=""),"",StartBal+SUM($D$6:D9)-SUM($E$6:E9)) -> 0
A10: 46054 | B10: 이번 달 용돈 | D10: 300000 | F10: =IF(AND(D10="",E10=""),"",StartBal+SUM($D$6:D10)-SUM($E$6:E10)) -> 0
A11: 46058 | B11: 예시 지출 | C11: 교재·학습 | E11: 90000 | F11: =IF(AND(D11="",E11=""),"",StartBal+SUM($D$6:D11)-SUM($E$6:E11)) -> 0
A12: 46065 | B12: 예시 지출 | C12: 취미·여가 | E12: 50000 | F12: =IF(AND(D12="",E12=""),"",StartBal+SUM($D$6:D12)-SUM($E$6:E12)) -> 0
A13: 46072 | B13: 예시 지출 | C13: 모임·경조사 | E13: 70000 | F13: =IF(AND(D13="",E13=""),"",StartBal+SUM($D$6:D13)-SUM($E$6:E13)) -> 0
A14: 46082 | B14: 이번 달 용돈 | D14: 300000 | F14: =IF(AND(D14="",E14=""),"",StartBal+SUM($D$6:D14)-SUM($E$6:E14)) -> 0
A15: 46086 | B15: 예시 지출 | C15: 취미·여가 | E15: 50000 | F15: =IF(AND(D15="",E15=""),"",StartBal+SUM($D$6:D15)-SUM($E$6:E15)) -> 0
A16: 46093 | B16: 예시 지출 | C16: 모임·경조사 | E16: 70000 | F16: =IF(AND(D16="",E16=""),"",StartBal+SUM($D$6:D16)-SUM($E$6:E16)) -> 0
A17: 46100 | B17: 예시 지출 | C17: 통신·구독 | E17: 90000 | F17: =IF(AND(D17="",E17=""),"",StartBal+SUM($D$6:D17)-SUM($E$6:E17)) -> 0
A18: 46113 | B18: 이번 달 용돈 | D18: 300000 | F18: =IF(AND(D18="",E18=""),"",StartBal+SUM($D$6:D18)-SUM($E$6:E18)) -> 0
A19: 46117 | B19: 예시 지출 | C19: 모임·경조사 | E19: 70000 | F19: =IF(AND(D19="",E19=""),"",StartBal+SUM($D$6:D19)-SUM($E$6:E19)) -> 0
A20: 46124 | B20: 예시 지출 | C20: 통신·구독 | E20: 90000 | F20: =IF(AND(D20="",E20=""),"",StartBal+SUM($D$6:D20)-SUM($E$6:E20)) -> 0
A21: 46131 | B21: 예시 지출 | C21: 저금 | E21: 50000 | F21: =IF(AND(D21="",E21=""),"",StartBal+SUM($D$6:D21)-SUM($E$6:E21)) -> 0
A22: 46143 | B22: 이번 달 용돈 | D22: 300000 | F22: =IF(AND(D22="",E22=""),"",StartBal+SUM($D$6:D22)-SUM($E$6:E22)) -> 0
A23: 46147 | B23: 예시 지출 | C23: 통신·구독 | E23: 90000 | F23: =IF(AND(D23="",E23=""),"",StartBal+SUM($D$6:D23)-SUM($E$6:E23)) -> 0
A24: 46154 | B24: 예시 지출 | C24: 저금 | E24: 50000 | F24: =IF(AND(D24="",E24=""),"",StartBal+SUM($D$6:D24)-SUM($E$6:E24)) -> 0
A25: 46161 | B25: 예시 지출 | C25: 기타 | E25: 70000 | F25: =IF(AND(D25="",E25=""),"",StartBal+SUM($D$6:D25)-SUM($E$6:E25)) -> 0
A26: 46174 | B26: 이번 달 용돈 | D26: 300000 | F26: =IF(AND(D26="",E26=""),"",StartBal+SUM($D$6:D26)-SUM($E$6:E26)) -> 0
A27: 46178 | B27: 예시 지출 | C27: 저금 | E27: 50000 | F27: =IF(AND(D27="",E27=""),"",StartBal+SUM($D$6:D27)-SUM($E$6:E27)) -> 0
A28: 46185 | B28: 예시 지출 | C28: 기타 | E28: 70000 | F28: =IF(AND(D28="",E28=""),"",StartBal+SUM($D$6:D28)-SUM($E$6:E28)) -> 0
A29: 46192 | B29: 예시 지출 | C29: 식비 | E29: 90000 | F29: =IF(AND(D29="",E29=""),"",StartBal+SUM($D$6:D29)-SUM($E$6:E29)) -> 0
F30: =IF(AND(D30="",E30=""),"",StartBal+SUM($D$6:D30)-SUM($E$6:E30)) -> 0
F31: =IF(AND(D31="",E31=""),"",StartBal+SUM($D$6:D31)-SUM($E$6:E31)) -> 0
F32: =IF(AND(D32="",E32=""),"",StartBal+SUM($D$6:D32)-SUM($E$6:E32)) -> 0
F33: =IF(AND(D33="",E33=""),"",StartBal+SUM($D$6:D33)-SUM($E$6:E33)) -> 0
F34: =IF(AND(D34="",E34=""),"",StartBal+SUM($D$6:D34)-SUM($E$6:E34)) -> 0
F35: =IF(AND(D35="",E35=""),"",StartBal+SUM($D$6:D35)-SUM($E$6:E35)) -> 0
F36: =IF(AND(D36="",E36=""),"",StartBal+SUM($D$6:D36)-SUM($E$6:E36)) -> 0
F37: =IF(AND(D37="",E37=""),"",StartBal+SUM($D$6:D37)-SUM($E$6:E37)) -> 0
F38: =IF(AND(D38="",E38=""),"",StartBal+SUM($D$6:D38)-SUM($E$6:E38)) -> 0
F39: =IF(AND(D39="",E39=""),"",StartBal+SUM($D$6:D39)-SUM($E$6:E39)) -> 0
F40: =IF(AND(D40="",E40=""),"",StartBal+SUM($D$6:D40)-SUM($E$6:E40)) -> 0
F41: =IF(AND(D41="",E41=""),"",StartBal+SUM($D$6:D41)-SUM($E$6:E41)) -> 0
...

Sheet 월요약
B1: 월 요약 (자동 계산)
B4: 월 | C4: 들어온 돈 | D4: 나간 돈 | E4: 남은 돈 | H4: 분류 | I4: 쓴 돈
B5: 1 | C5: =SUMIFS('기입장'!$D$6:$D$305,'기입장'!$A$6:$A$305,">="&DATE(Year,B5,1),'기입장'!$A$6:$A$305,"<"&DATE(Year,B5+1,1)) -> 0 | D5: =SUMIFS('기입장'!$E$6:$E$305,'기입장'!$A$6:$A$305,">="&DATE(Year,B5,1),'기입장'!$A$6:$A$305,"<"&DATE(Year,B5+1,1)) -> 0 | E5: =C5-D5 -> 0 | H5: 식비 | I5: =SUMIFS('기입장'!$E$6:$E$305,'기입장'!$C$6:$C$305,H5) -> 0
B6: 2 | C6: =SUMIFS('기입장'!$D$6:$D$305,'기입장'!$A$6:$A$305,">="&DATE(Year,B6,1),'기입장'!$A$6:$A$305,"<"&DATE(Year,B6+1,1)) -> 0 | D6: =SUMIFS('기입장'!$E$6:$E$305,'기입장'!$A$6:$A$305,">="&DATE(Year,B6,1),'기입장'!$A$6:$A$305,"<"&DATE(Year,B6+1,1)) -> 0 | E6: =C6-D6 -> 0 | H6: 교통 | I6: =SUMIFS('기입장'!$E$6:$E$305,'기입장'!$C$6:$C$305,H6) -> 0
B7: 3 | C7: =SUMIFS('기입장'!$D$6:$D$305,'기입장'!$A$6:$A$305,">="&DATE(Year,B7,1),'기입장'!$A$6:$A$305,"<"&DATE(Year,B7+1,1)) -> 0 | D7: =SUMIFS('기입장'!$E$6:$E$305,'기입장'!$A$6:$A$305,">="&DATE(Year,B7,1),'기입장'!$A$6:$A$305,"<"&DATE(Year,B7+1,1)) -> 0 | E7: =C7-D7 -> 0 | H7: 교재·학습 | I7: =SUMIFS('기입장'!$E$6:$E$305,'기입장'!$C$6:$C$305,H7) -> 0
B8: 4 | C8: =SUMIFS('기입장'!$D$6:$D$305,'기입장'!$A$6:$A$305,">="&DATE(Year,B8,1),'기입장'!$A$6:$A$305,"<"&DATE(Year,B8+1,1)) -> 0 | D8: =SUMIFS('기입장'!$E$6:$E$305,'기입장'!$A$6:$A$305,">="&DATE(Year,B8,1),'기입장'!$A$6:$A$305,"<"&DATE(Year,B8+1,1)) -> 0 | E8: =C8-D8 -> 0 | H8: 취미·여가 | I8: =SUMIFS('기입장'!$E$6:$E$305,'기입장'!$C$6:$C$305,H8) -> 0
B9: 5 | C9: =SUMIFS('기입장'!$D$6:$D$305,'기입장'!$A$6:$A$305,">="&DATE(Year,B9,1),'기입장'!$A$6:$A$305,"<"&DATE(Year,B9+1,1)) -> 0 | D9: =SUMIFS('기입장'!$E$6:$E$305,'기입장'!$A$6:$A$305,">="&DATE(Year,B9,1),'기입장'!$A$6:$A$305,"<"&DATE(Year,B9+1,1)) -> 0 | E9: =C9-D9 -> 0 | H9: 모임·경조사 | I9: =SUMIFS('기입장'!$E$6:$E$305,'기입장'!$C$6:$C$305,H9) -> 0
B10: 6 | C10: =SUMIFS('기입장'!$D$6:$D$305,'기입장'!$A$6:$A$305,">="&DATE(Year,B10,1),'기입장'!$A$6:$A$305,"<"&DATE(Year,B10+1,1)) -> 0 | D10: =SUMIFS('기입장'!$E$6:$E$305,'기입장'!$A$6:$A$305,">="&DATE(Year,B10,1),'기입장'!$A$6:$A$305,"<"&DATE(Year,B10+1,1)) -> 0 | E10: =C10-D10 -> 0 | H10: 통신·구독 | I10: =SUMIFS('기입장'!$E$6:$E$305,'기입장'!$C$6:$C$305,H10) -> 0
B11: 7 | C11: =SUMIFS('기입장'!$D$6:$D$305,'기입장'!$A$6:$A$305,">="&DATE(Year,B11,1),'기입장'!$A$6:$A$305,"<"&DATE(Year,B11+1,1)) -> 0 | D11: =SUMIFS('기입장'!$E$6:$E$305,'기입장'!$A$6:$A$305,">="&DATE(Year,B11,1),'기입장'!$A$6:$A$305,"<"&DATE(Year,B11+1,1)) -> 0 | E11: =C11-D11 -> 0 | H11: 저금 | I11: =SUMIFS('기입장'!$E$6:$E$305,'기입장'!$C$6:$C$305,H11) -> 0
B12: 8 | C12: =SUMIFS('기입장'!$D$6:$D$305,'기입장'!$A$6:$A$305,">="&DATE(Year,B12,1),'기입장'!$A$6:$A$305,"<"&DATE(Year,B12+1,1)) -> 0 | D12: =SUMIFS('기입장'!$E$6:$E$305,'기입장'!$A$6:$A$305,">="&DATE(Year,B12,1),'기입장'!$A$6:$A$305,"<"&DATE(Year,B12+1,1)) -> 0 | E12: =C12-D12 -> 0 | H12: 기타 | I12: =SUMIFS('기입장'!$E$6:$E$305,'기입장'!$C$6:$C$305,H12) -> 0
B13: 9 | C13: =SUMIFS('기입장'!$D$6:$D$305,'기입장'!$A$6:$A$305,">="&DATE(Year,B13,1),'기입장'!$A$6:$A$305,"<"&DATE(Year,B13+1,1)) -> 0 | D13: =SUMIFS('기입장'!$E$6:$E$305,'기입장'!$A$6:$A$305,">="&DATE(Year,B13,1),'기입장'!$A$6:$A$305,"<"&DATE(Year,B13+1,1)) -> 0 | E13: =C13-D13 -> 0 | H13: 합계 | I13: =SUM(I5:I12) -> 0
B14: 10 | C14: =SUMIFS('기입장'!$D$6:$D$305,'기입장'!$A$6:$A$305,">="&DATE(Year,B14,1),'기입장'!$A$6:$A$305,"<"&DATE(Year,B14+1,1)) -> 0 | D14: =SUMIFS('기입장'!$E$6:$E$305,'기입장'!$A$6:$A$305,">="&DATE(Year,B14,1),'기입장'!$A$6:$A$305,"<"&DATE(Year,B14+1,1)) -> 0 | E14: =C14-D14 -> 0
B15: 11 | C15: =SUMIFS('기입장'!$D$6:$D$305,'기입장'!$A$6:$A$305,">="&DATE(Year,B15,1),'기입장'!$A$6:$A$305,"<"&DATE(Year,B15+1,1)) -> 0 | D15: =SUMIFS('기입장'!$E$6:$E$305,'기입장'!$A$6:$A$305,">="&DATE(Year,B15,1),'기입장'!$A$6:$A$305,"<"&DATE(Year,B15+1,1)) -> 0 | E15: =C15-D15 -> 0
B16: 12 | C16: =SUMIFS('기입장'!$D$6:$D$305,'기입장'!$A$6:$A$305,">="&DATE(Year,B16,1),'기입장'!$A$6:$A$305,"<"&DATE(Year,B16+1,1)) -> 0 | D16: =SUMIFS('기입장'!$E$6:$E$305,'기입장'!$A$6:$A$305,">="&DATE(Year,B16,1),'기입장'!$A$6:$A$305,"<"&DATE(Year,B16+1,1)) -> 0 | E16: =C16-D16 -> 0
B17: 합계 | C17: =SUM(C5:C16) -> 0 | D17: =SUM(D5:D16) -> 0 | E17: =SUM(E5:E16) -> 0

Sheet 저금목표
B1: 저금 목표 — 얼마나 모았을까요?
B3: 갖고 싶은 것 | C3: 노트북·태블릿
B4: 목표 금액(원) | C4: 1800000
B6: 지금 모은 돈(저금 포함) | C6: =StartBal+SUM('기입장'!$D$6:$D$305)-SUM('기입장'!$E$6:$E$305)+SUMIFS('기입장'!$E$6:$E$305,'기입장'!$C$6:$C$305,"저금") -> 0
B7: 모은 비율 | C7: =IF(C4=0,0,C6/C4) -> 0
B8: 더 모아야 할 돈 | C8: =MAX(0,C4-C6) -> 0
B9: 한 달 평균 남는 돈 | C9: =IFERROR(AVERAGEIF('월요약'!$E$5:$E$16,"<>0"),0) -> 0
B10: 달성까지 예상 기간 | C10: =IF(C9<=0,"-",IF(C8=0,"달성!",ROUNDUP(C8/C9,0)&"개월")) -> 0
B12: 막대가 가득 차면 목표를 이룬 거예요. 잘 모으고 있어요, 계속 해 봐요!
